<?xml version="1.0"?>
<robot name="xianquzhe1_base" xmlns:xacro="http://www.ros.org/wiki/xacro">
 <!-- PROPERTY LIST -->
    <xacro:property name="M_PI" value="3.1415926"/>
	
	

 <!-- Macro for inertia matrix -->
    <xacro:macro name="sphere_inertial_matrix" params="m r">
        <inertial>
            <mass value="${m}" />
            <inertia ixx="${2*m*r*r/5}" ixy="0" ixz="0"
                iyy="${2*m*r*r/5}" iyz="0" 
                izz="${2*m*r*r/5}" />
        </inertial>
    </xacro:macro>

    <xacro:macro name="cylinder_inertial_matrix" params="m r h">
        <inertial>
            <mass value="${m}" />
            <inertia ixx="${m*(3*r*r+h*h)/12}" ixy = "0" ixz = "0"
                iyy="${m*(3*r*r+h*h)/12}" iyz = "0"
                izz="${m*r*r/2}" /> 
        </inertial>
    </xacro:macro>

<xacro:macro name="xianquzhe1_base" params="prefix:=xianquzhe_base">	
 
    

     <link name="base_footprint">
            <visual>
                <origin xyz="0 0 0" rpy="0 0 0" />
                <geometry>
                    <box size="0.001 0.001 0.001" />
                </geometry>
            </visual>
     </link>
 
	  
     <joint name="base_footprint_joint" type="fixed">
            <origin xyz="0 0 0" rpy="0 0 0" />        
            <parent link="base_footprint"/>
            <child link="base_link" />
     </joint>
	 
	 
  <link
    name="base_link">
    <inertial>
      <origin
        xyz="0 0.05 0.2"
        rpy="0 0 0" />
      <mass
        value="300" />
      <inertia
        ixx="500"
        ixy="0"
        ixz="0"
        iyy="500"
        iyz="0"
        izz="500" />
    </inertial>
    <visual>
      <origin
        xyz="0 0 0"
        rpy="0 0 0" />
      <geometry>
        <mesh
          filename="package://xianquzhe/meshes/xianquzhe/base_link.STL" />
      </geometry>
      <material
        name="">
        <color
          rgba="1 0.50196 0.25098 1" />
      </material>
    </visual>
    <collision>
      <origin
        xyz="0 0 0.001"
        rpy="0 0 0" />
      <geometry>
        <mesh
          filename="package://xianquzhe/meshes/xianquzhe/base_link.STL" />
      </geometry>
    </collision>
  </link>
  <link
    name="Upper">
    <inertial>
      <origin
        xyz="0.11386 -1.1102E-16 -0.1008"
        rpy="0 0 0" />
      <mass
        value="5" />
      <inertia ixx="10" ixy="0" ixz="0" iyy="10" iyz="0" izz="10" />
    </inertial>
    <visual>
      <origin
        xyz="0 0 0"
        rpy="0 0 0" />
      <geometry>
        <mesh
          filename="package://xianquzhe/meshes/xianquzhe/Upper.STL" />
      </geometry>
      <material
        name="">
        <color
          rgba="0.89804 0.91765 0.92941 1" />
      </material>
    </visual>
    <collision>
      <origin
        xyz="0 0 0"
        rpy="0 0 0" />
      <geometry>
        <mesh
          filename="package://xianquzhe/meshes/xianquzhe/Upper.STL" />
      </geometry>
    </collision>
  </link>
  <joint
    name="Upper_joint"
    type="prismatic">
    <origin
      xyz="0 -0.531 0.918"
      rpy="1.5708 -1.5708 0" />
    <parent
      link="base_link" />
    <child
      link="Upper" />
    <axis
      xyz="1 0 0" />
    <limit
      lower="0"
      upper="1"
      effort="500"
      velocity="2" />
  </joint>
  
  <!-- gazebo color -->
        <gazebo reference="base_link">
            <material>Gazebo/Grey</material>
        </gazebo>
		
		<gazebo reference="Upper">
            <material>Gazebo/Orange</material>
        </gazebo>
<!-- ros_control plugin-->
        <transmission name="Upper_joint_trans">
            <type>transmission_interface/SimpleTransmission</type>
            <joint name="Upper_joint" >
                <hardwareInterface>hardware_interface/PositionJointInterface</hardwareInterface>
            </joint>
            <actuator name="Upper_joint_motor">
                <hardwareInterface>hardware_interface/PositionJointInterface</hardwareInterface>
                <mechanicalReduction>1</mechanicalReduction>
            </actuator>
        </transmission>
<!-- ros_control plugin -->
        <gazebo>
            <plugin name="gazebo_ros_control" filename="libgazebo_ros_control.so">
                <robotNamespace>/xianquzhe1</robotNamespace>
                <robotSimType>gazebo_ros_control/DefaultRobotHWSim</robotSimType>
                <legacyModeNS>true</legacyModeNS>
            </plugin>
        </gazebo>

<!-- move controller --> 
    <gazebo>
    <plugin name="object_controller" filename="libgazebo_ros_planar_move.so">
      <commandTopic>cmd_vel</commandTopic>
      <odometryTopic>odom</odometryTopic>
      <odometryFrame>odom</odometryFrame>
      <odometryRate>20.0</odometryRate>
      <robotBaseFrame>base_link</robotBaseFrame>
    </plugin>
  </gazebo>
  
</xacro:macro>
	
	
</robot>