<?xml version="1.0"?>
<robot xmlns:sensor="http://playerstage.sourceforge.net/gazebo/xmlschema/#sensor" 
       xmlns:controller="http://playerstage.sourceforge.net/gazebo/xmlschema/#controller" 
       xmlns:interface="http://playerstage.sourceforge.net/gazebo/xmlschema/#interface" 
       xmlns:xacro="http://www.ros.org/wiki/xacro/#interface">
 
  <xacro:include filename="$(find pr_description)/urdf/rod_climb/rod_climb.gazebo.xacro"/>
  <xacro:include filename="$(find pr_description)/urdf/rod_climb/rod_climb.transmission.xacro"/>
  
  <xacro:property name="M_PI" value="3.1415926535897931" />

  <xacro:macro name="rod_climb" params="transmission_hw_interface" >

    <link name="rod_link">
      <visual>
        <origin xyz="0 0 0.000" rpy="0 0 0"/>
        <geometry>
        <mesh filename="package://pr_description/meshes/rod_climb/rod_link.STL" />
        </geometry>
        <material name="prrobot/Green"/>
      </visual>
      <collision>
        <origin xyz="0 0 0.000" rpy="0 0 0"/>
        <geometry>
          <mesh filename="package://pr_description/meshes/rod_climb/rod_link.STL" />
        </geometry>
      </collision>
      <inertial>
        <origin xyz="0 -6.2235E-19 2.1937" rpy="0 0 0" />
        <mass value="16.894" />
        <inertia
          ixx="27.051" ixy="-9.9834E-35" ixz="3.4607E-32"
          iyy="27.051" iyz="-1.4646E-17"
          izz="0.011319" 
        />
      </inertial>
    </link>

    <joint name="rodclimbing_joint1" type="prismatic">
      <origin xyz="0 0 1.2119" rpy="0 0 0" />
      <parent link="rod_link" />
      <child link="rodclimbing_link1" />
      <axis xyz="0 0 1" />
      <limit lower="-0.5" upper="3.5" effort="150" velocity="10" />
      <dynamics damping="0.0" friction="0.0"/>
    </joint>

    <link name="rodclimbing_link1">
      <inertial>
        <origin xyz="0 6.2985E-18 0.018077" rpy="0 0 0" />
        <mass value="1.8598" />
        <inertia
          ixx="0.32672" ixy="2.3135E-17" ixz="6.8526E-18"
          iyy="0.50579" iyz="4.0943E-18"
          izz="0.24065" />
      </inertial>
      <visual>
        <origin xyz="0 0 0" rpy="0 0 0" />
        <geometry>
          <mesh filename="package://pr_description/meshes/rod_climb/rodclimbing_link1.STL" />
        </geometry>
      <material name="">
        <color rgba="1 0.76863 0.52941 1" />
      </material>
      </visual>
      <collision>
        <origin xyz="0 0 0" rpy="0 0 0" />
        <geometry>
          <mesh filename="package://pr_description/meshes/rod_climb/rodclimbing_link1.STL" />
        </geometry>
      </collision>
    </link>

    <joint name="rodclimbing_joint2" type="revolute">
      <origin xyz="0 0 0" rpy="0 0 0" />
      <parent link="rodclimbing_link1" />
      <child link="rodclimbing_link2" />
      <axis xyz="0 0 1" />
      <limit lower="-1.58" upper="3.1415" effort="150" velocity="10" />
      <dynamics damping="0.0" friction="0.0"/>
    </joint>

    <link name="rodclimbing_link2">
      <inertial>
        <origin xyz="0.1988 2.2054E-17 0.021699" rpy="0 0 0" />
        <mass value="0.38049" />
        <inertia
          ixx="0.11933" ixy="1.6193E-18" ixz="0.00018714"
          iyy="0.16013" iyz="-2.2588E-18"
          izz="0.053296" />
      </inertial>
      <visual>
        <origin xyz="0 0 0" rpy="0 0 0" />
        <geometry>
          <mesh filename="package://pr_description/meshes/rod_climb/rodclimbing_link2.STL" />
        </geometry>
        <material
          name="">
          <color
            rgba="1 0.76863 0.52941 1" />
        </material>
      </visual>
      <collision>
        <origin xyz="0 0 0" rpy="0 0 0" />
        <geometry>
          <mesh filename="package://pr_description/meshes/rod_climb/rodclimbing_link2.STL" />
        </geometry>
      </collision>
    </link>

    <!-- extensions -->
    <xacro:rod_climb_gazebo />
    <xacro:rod_climb_transmission hw_interface="${transmission_hw_interface}" />

  </xacro:macro>
</robot>
